Workbook

Sheet Dashboard
B2: 🌍 GLOBAL CARBON PRICING DASHBOARD
B3: ▼ INTERACTIVE FILTERS
B4: Region | C4: Policy Type | D4: Year From | E4: Year To
B5: All | C5: All | D5: 2019 | E5: 2023
B7: JURISDICTIONS | D7: AVG PRICE ($/tCO2) | F7: AVG EMISSIONS (MtCO2) | H7: EST. REVENUE ($B)
B8: =IFERROR(SUMPRODUCT((($B$5="All")*(Analysis!$K$3:$K$500+Analysis!$L$3:$L$500+Analysis!$M$3:$M$500+Analysis!$N$3:$N$500+Analysis!$O$3:$O$500+Analysis!$P$3:$P$500)+(($B$5="Africa")*Analysis!$K$3:$K$500)+(($B$5="Asia-Pacific")*Analysis!$L$3:$L$500)+(($B$5="Europe")*Analysis!$M$3:$M$500)+(($B$5="Latin America")*Analysis!$N$3:$N$500)+(($B$5="North America")*Analysis!$O$3:$O$500)+(($B$5="Other")*Analysis!$P$3:$P$500))*(Analysis!$S$3:$S$500)),0) -> 63 | D8: =IFERROR(ROUND(SUMPRODUCT((($B$5="All")*(Analysis!$K$3:$K$500+Analysis!$L$3:$L$500+Analysis!$M$3:$M$500+Analysis!$N$3:$N$500+Analysis!$O$3:$O$500+Analysis!$P$3:$P$500)+(($B$5="Africa")*Analysis!$K$3:$K$500)+(($B$5="Asia-Pacific")*Analysis!$L$3:$L$500)+(($B$5="Europe")*Analysis!$M$3:$M$500)+(($B$5="Latin America")*Analysis!$N$3:$N$500)+(($B$5="North America")*Analysis!$O$3:$O$500)+(($B$5="Other")*Analysis!$P$3:$P$500))*(($C$5="All")*(Analysis!$Q$3:$Q$500+Analysis!$R$3:$R$500)+(($C$5="Carbon tax")*Analysis!$Q$3:$Q$500)+(($C$5="ETS")*Analysis!$R$3:$R$500))*(Analysis!$B$3:$B$500>=$D$5)*(Analysis!$B$3:$B$500<=$E$5)*Analysis!$C$3:$C$500)/SUMPRODUCT((($B$5="All")*(Analysis!$K$3:$K$500+Analysis!$L$3:$L$500+Analysis!$M$3:$M$500+Analysis!$N$3:$N$500+Analysis!$O$3:$O$500+Analysis!$P$3:$P$500)+(($B$5="Africa")*Analysis!$K$3:$K$500)+(($B$5="Asia-Pacific")*Analysis!$L$3:$L$500)+(($B$5="Europe")*Analysis!$M$3:$M$500)+(($B$5="Latin America")*Analysis!$N$3:$N$500)+(($B$5="North America")*Analysis!$O$3:$O$500)+(($B$5="Other")*Analysis!$P$3:$P$500))*(($C$5="All")*(Analysis!$Q$3:$Q$500+Analysis!$R$3:$R$500)+(($C$5="Carbon tax")*Analysis!$Q$3:$Q$500)+(($C$5="ETS")*Analysis!$R$3:$R$500))*(Analysis!$B$3:$B$500>=$D$5)*(Analysis!$B$3:$B$500<=$E$5)),1),"-") -> 23.6 | F8: =IFERROR(ROUND(SUMPRODUCT((($B$5="All")*(Analysis!$K$3:$K$500+Analysis!$L$3:$L$500+Analysis!$M$3:$M$500+Analysis!$N$3:$N$500+Analysis!$O$3:$O$500+Analysis!$P$3:$P$500)+(($B$5="Africa")*Analysis!$K$3:$K$500)+(($B$5="Asia-Pacific")*Analysis!$L$3:$L$500)+(($B$5="Europe")*Analysis!$M$3:$M$500)+(($B$5="Latin America")*Analysis!$N$3:$N$500)+(($B$5="North America")*Analysis!$O$3:$O$500)+(($B$5="Other")*Analysis!$P$3:$P$500))*(($C$5="All")*(Analysis!$Q$3:$Q$500+Analysis!$R$3:$R$500)+(($C$5="Carbon tax")*Analysis!$Q$3:$Q$500)+(($C$5="ETS")*Analysis!$R$3:$R$500))*(Analysis!$B$3:$B$500>=$D$5)*(Analysis!$B$3:$B$500<=$E$5)*Analysis!$E$3:$E$500)/SUMPRODUCT((($B$5="All")*(Analysis!$K$3:$K$500+Analysis!$L$3:$L$500+Analysis!$M$3:$M$500+Analysis!$N$3:$N$500+Analysis!$O$3:$O$500+Analysis!$P$3:$P$500)+(($B$5="Africa")*Analysis!$K$3:$K$500)+(($B$5="Asia-Pacific")*Analysis!$L$3:$L$500)+(($B$5="Europe")*Analysis!$M$3:$M$500)+(($B$5="Latin America")*Analysis!$N$3:$N$500)+(($B$5="North America")*Analysis!$O$3:$O$500)+(($B$5="Other")*Analysis!$P$3:$P$500))*(($C$5="All")*(Analysis!$Q$3:$Q$500+Analysis!$R$3:$R$500)+(($C$5="Carbon tax")*Analysis!$Q$3:$Q$500)+(($C$5="ETS")*Analysis!$R$3:$R$500))*(Analysis!$B$3:$B$500>=$D$5)*(Analysis!$B$3:$B$500<=$E$5)),0),"-") -> 2574 | H8: =IFERROR(ROUND(SUMPRODUCT((($B$5="All")*(Analysis!$K$3:$K$500+Analysis!$L$3:$L$500+Analysis!$M$3:$M$500+Analysis!$N$3:$N$500+Analysis!$O$3:$O$500+Analysis!$P$3:$P$500)+(($B$5="Africa")*Analysis!$K$3:$K$500)+(($B$5="Asia-Pacific")*Analysis!$L$3:$L$500)+(($B$5="Europe")*Analysis!$M$3:$M$500)+(($B$5="Latin America")*Analysis!$N$3:$N$500)+(($B$5="North America")*Analysis!$O$3:$O$500)+(($B$5="Other")*Analysis!$P$3:$P$500))*(($C$5="All")*(Analysis!$Q$3:$Q$500+Analysis!$R$3:$R$500)+(($C$5="Carbon tax")*Analysis!$Q$3:$Q$500)+(($C$5="ETS")*Analysis!$R$3:$R$500))*(Analysis!$B$3:$B$500>=$D$5)*(Analysis!$B$3:$B$500<=$E$5)*Analysis!$G$3:$G$500)/1000,0),"-") -> 2157
B10: BREAKDOWN BY REGION · Full dataset (2015–2023 · All policies)
B11: Region | C11: Jurisdictions | D11: Avg Price ($/tCO2) | E11: Avg Emissions (MtCO2) | F11: Revenue ($B) | G11: Policy Split | H11: Period
B12: Africa | C12: 1 | D12: 8.7 | E12: 439 | F12: 5 | G12: 4 tax / 0 ETS | H12: 2015–2023
B13: Asia-Pacific | C13: 13 | D13: 5.8 | E13: 8753 | F13: 1274 | G13: 14 tax / 86 ETS | H13: 2015–2023
B14: Europe | C14: 20 | D14: 31.8 | E14: 320 | F14: 481 | G14: 137 tax / 24 ETS | H14: 2015–2023
B15: Latin America | C15: 8 | D15: 13.5 | E15: 448 | F15: 40 | G15: 39 tax / 0 ETS | H15: 2015–2023
B16: North America | C16: 5 | D16: 26.1 | E16: 1970 | F16: 546 | G16: 17 tax / 25 ETS | H16: 2015–2023
B17: Other | C17: 16 | D17: 20.3 | E17: 1588 | F17: 589 | G17: 22 tax / 64 ETS | H17: 2015–2023
B18: GLOBAL TOTAL | C18: 63 | D18: 21.1 | E18: 2698 | F18: 2934 | G18: 233 tax / 199 ETS | H18: 2015–2023
B20: KPIs respond to all 4 filters · Table shows full dataset · Revenue = Price × Emissions × 0.30 · Source: World Bank 2024

Sheet Analysis
A1: Jurisdiction | B1: Year | C1: Carbon_Price_USD | D1: Policy_Type | E1: Emissions_MtCO2 | F1: Region | G1: Revenue_Proxy_MUSD | H1: Price_Intensity | I1: Log_Price | J1: Log_Emissions | K1: D_Africa | L1: D_Asia-Pacific | M1: D_Europe | N1: D_Latin America | O1: D_North America | P1: D_Other | Q1: D_CarbonTax | R1: D_ETS | S1: Juris_First
A2: Jurisdiction name | B2: Calendar year | C2: Nominal USD per tCO2 | D2: Carbon tax or ETS | E2: Total national/sub-national emissions | F2: World region | G2: Estimated revenue ($/tCO2 × MtCO2 × 0.30) | H2: Price per unit emissions | I2: ln(Price) for econometric regression | J2: ln(Emissions) for regression | K2: Dummy variable: 1=D_Africa | L2: Dummy variable: 1=D_Asia-Pacific | M2: Dummy variable: 1=D_Europe | N2: Dummy variable: 1=D_Latin America | O2: Dummy variable: 1=D_North America | P2: Dummy variable: 1=D_Other | Q2: Dummy variable: 1=D_CarbonTax | R2: Dummy variable: 1=D_ETS | S2: Dummy variable: 1=Juris_First
A3: Alberta | B3: 2015 | C3: 11.89 | D3: ETS | E3: 789.07 | F3: North America | G3: 2814.6127 | H3: 0.015049299 | I3: 2.4757 | J3: 6.6709 | K3: 0 | L3: 0 | M3: 0 | N3: 0 | O3: 1 | P3: 0 | Q3: 0 | R3: 1 | S3: 1
A4: Alberta | B4: 2016 | C4: 15.37 | D4: ETS | E4: 886.24 | F4: North America | G4: 4086.4526 | H4: 0.017323385 | I4: 2.7324 | J4: 6.787 | K4: 0 | L4: 0 | M4: 0 | N4: 0 | O4: 1 | P4: 0 | Q4: 0 | R4: 1 | S4: 0
A5: Alberta | B5: 2017 | C5: 15.03 | D5: Carbon tax | E5: 905.03 | F5: North America | G5: 4080.7803 | H5: 0.016588855 | I5: 2.71 | J5: 6.808 | K5: 0 | L5: 0 | M5: 0 | N5: 0 | O5: 1 | P5: 0 | Q5: 1 | R5: 0 | S5: 0
A6: Alberta | B6: 2017 | C6: 22.54 | D6: ETS | E6: 905.03 | F6: North America | G6: 6119.8129 | H6: 0.024877763 | I6: 3.1153 | J6: 6.808 | K6: 0 | L6: 0 | M6: 0 | N6: 0 | O6: 1 | P6: 0 | Q6: 0 | R6: 1 | S6: 0
A7: Alberta | B7: 2018 | C7: 23.25 | D7: Carbon tax | E7: 923.96 | F7: North America | G7: 6444.621 | H7: 0.025136222 | I7: 3.1463 | J7: 6.8287 | K7: 0 | L7: 0 | M7: 0 | N7: 0 | O7: 1 | P7: 0 | Q7: 1 | R7: 0 | S7: 0
A8: Alberta | B8: 2018 | C8: 23.25 | D8: ETS | E8: 923.96 | F8: North America | G8: 6444.621 | H8: 0.025136222 | I8: 3.1463 | J8: 6.8287 | K8: 0 | L8: 0 | M8: 0 | N8: 0 | O8: 1 | P8: 0 | Q8: 0 | R8: 1 | S8: 0
A9: Alberta | B9: 2019 | C9: 22.49 | D9: Carbon tax | E9: 915.12 | F9: North America | G9: 6174.3146 | H9: 0.024549186 | I9: 3.1131 | J9: 6.8191 | K9: 0 | L9: 0 | M9: 0 | N9: 0 | O9: 1 | P9: 0 | Q9: 1 | R9: 0 | S9: 0
A10: Alberta | B10: 2019 | C10: 22.49 | D10: ETS | E10: 915.12 | F10: North America | G10: 6174.3146 | H10: 0.024549186 | I10: 3.1131 | J10: 6.8191 | K10: 0 | L10: 0 | M10: 0 | N10: 0 | O10: 1 | P10: 0 | Q10: 0 | R10: 1 | S10: 0
A11: Alberta | B11: 2020 | C11: 21.1 | D11: ETS | E11: 853.61 | F11: North America | G11: 5403.3513 | H11: 0.024689625 | I11: 3.0493 | J11: 6.7495 | K11: 0 | L11: 0 | M11: 0 | N11: 0 | O11: 1 | P11: 0 | Q11: 0 | R11: 1 | S11: 0
A12: Alberta | B12: 2021 | C12: 31.83 | D12: ETS | E12: 844.41 | F12: North America | G12: 8063.2711 | H12: 0.037650371 | I12: 3.4604 | J12: 6.7386 | K12: 0 | L12: 0 | M12: 0 | N12: 0 | O12: 1 | P12: 0 | Q12: 0 | R12: 1 | S12: 0
A13: Alberta | B13: 2022 | C13: 39.96 | D13: ETS | E13: 857.27 | F13: North America | G13: 10276.953 | H13: 0.046558775 | I13: 3.6879 | J13: 6.7538 | K13: 0 | L13: 0 | M13: 0 | N13: 0 | O13: 1 | P13: 0 | Q13: 0 | R13: 1 | S13: 0
A14: Alberta | B14: 2023 | C14: 48.03 | D14: ETS | E14: 875.95 | F14: North America | G14: 12621.564 | H14: 0.054769371 | I14: 3.8718 | J14: 6.7753 | K14: 0 | L14: 0 | M14: 0 | N14: 0 | O14: 1 | P14: 0 | Q14: 0 | R14: 1 | S14: 0
... A82: Colombia | B82: 2020 | C82: 4.24 | D82: Carbon tax | E82: 288.5 | F82: Latin America | G82: 366.972 | H82: 0.014645941 | I82: 1.4446 | J82: 5.6647 | K82: 0 | L82: 0 | M82: 0 | N82: 1 | O82: 0 | P82: 0 | Q82: 1 | R82: 0 | S82: 0
A83: Colombia | B83: 2021 | C83: 0 | D83: Carbon tax | E83: 284.59 | F83: Latin America | G83: 0 | H83: 0 | J83: 5.651 | K83: 0 | L83: 0 | M83: 0 | N83: 1 | O83: 0 | P83: 0 | Q83: 1 | R83: 0 | S83: 0
A84: Colombia | B84: 2022 | C84: 5.01 | D84: Carbon tax | E84: 289.18 | F84: Latin America | G84: 434.63754 | H84: 0.017265146 | I84: 1.6114 | J84: 5.667 | K84: 0 | L84: 0 | M84: 0 | N84: 1 | O84: 0 | P84: 0 | Q84: 1 | R84: 0 | S84: 0
A85: Colombia | B85: 2023 | C85: 5.06 | D85: Carbon tax | E85: 294.08 | F85: Latin America | G85: 446.41344 | H85: 0.017147892 | I85: 1.6214 | J85: 5.6839 | K85: 0 | L85: 0 | M85: 0 | N85: 1 | O85: 0 | P85: 0 | Q85: 1 | R85: 0 | S85: 0
A86: Denmark | B86: 2015 | C86: 24.47 | D86: Carbon tax | E86: 47.1 | F86: Europe | G86: 345.7611 | H86: 0.50873181 | I86: 3.1974 | J86: 3.8523 | K86: 0 | L86: 0 | M86: 1 | N86: 0 | O86: 0 | P86: 0 | Q86: 1 | R86: 0 | S86: 1
A87: Denmark | B87: 2016 | C87: 25.61 | D87: Carbon tax | E87: 51.43 | F87: Europe | G87: 395.13669 | H87: 0.4884608 | I87: 3.243 | J87: 3.9402 | K87: 0 | L87: 0 | M87: 1 | N87: 0 | O87: 0 | P87: 0 | Q87: 1 | R87: 0 | S87: 0
A88: Denmark | B88: 2017 | C88: 24.78 | D88: Carbon tax | E88: 49.09 | F88: Europe | G88: 364.93506 | H88: 0.49470952 | I88: 3.21 | J88: 3.8937 | K88: 0 | L88: 0 | M88: 1 | N88: 0 | O88: 0 | P88: 0 | Q88: 1 | R88: 0 | S88: 0
A89: Denmark | B89: 2018 | C89: 28.82 | D89: Carbon tax | E89: 48.81 | F89: Europe | G89: 422.01126 | H89: 0.57859867 | I89: 3.3611 | J89: 3.8879 | K89: 0 | L89: 0 | M89: 1 | N89: 0 | O89: 0 | P89: 0 | Q89: 1 | R89: 0 | S89: 0
A90: Denmark | B90: 2019 | C90: 26.39 | D90: Carbon tax | E90: 45.11 | F90: Europe | G90: 357.13587 | H90: 0.57232704 | I90: 3.273 | J90: 3.8091 | K90: 0 | L90: 0 | M90: 1 | N90: 0 | O90: 0 | P90: 0 | Q90: 1 | R90: 0 | S90: 0
A91: Denmark | B91: 2020 | C91: 25.93 | D91: Carbon tax | E91: 42.86 | F91: Europe | G91: 333.40794 | H91: 0.59119927 | I91: 3.2554 | J91: 3.7579 | K91: 0 | L91: 0 | M91: 1 | N91: 0 | O91: 0 | P91: 0 | Q91: 1 | R91: 0 | S91: 0
A92: Denmark | B92: 2021 | C92: 28.14 | D92: Carbon tax | E92: 42.36 | F92: Europe | G92: 357.60312 | H92: 0.64898524 | I92: 3.3372 | J92: 3.7462 | K92: 0 | L92: 0 | M92: 1 | N92: 0 | O92: 0 | P92: 0 | Q92: 1 | R92: 0 | S92: 0
A93: Denmark | B93: 2022 | C93: 26.62 | D93: Carbon tax | E93: 40.64 | F93: Europe | G93: 324.55104 | H93: 0.63928915 | I93: 3.2817 | J93: 3.7048 | K93: 0 | L93: 0 | M93: 1 | N93: 0 | O93: 0 | P93: 0 | Q93: 1 | R93: 0 | S93: 0
A94: Denmark | B94: 2023 | C94: 26.53 | D94: Carbon tax | E94: 38.04 | F94: Europe | G94: 302.76036 | H94: 0.67955943 | I94: 3.2783 | J94: 3.6386 | K94: 0 | L94: 0 | M94: 1 | N94: 0 | O94: 0 | P94: 0 | Q94: 1 | R94: 0 | S94: 0
A95: EU | B95: 2015 | C95: 7.68 | D95: ETS | E95: 3242.91 | F95: Europe | G95: 7471.6646 | H95: 0.0023675133 | I95: 2.0386 | J95: 8.0842 | K95: 0 | L95: 0 | M95: 1 | N95: 0 | O95: 0 | P95: 0 | Q95: 0 | R95: 1 | S95: 1
... A434: Zacatecas | B434: 2023 | C434: 13.86 | D434: Carbon tax | E434: 731.02 | F434: Latin America | G434: 3039.5812 | H434: 0.018933909 | I434: 2.629 | J434: 6.5944 | K434: 0 | L434: 0 | M434: 0 | N434: 1 | O434: 0 | P434: 0 | Q434: 1 | R434: 0 | S434: 0

Sheet Chart_Heatmap
A1: CARBON PRICE HEATMAP BY JURISDICTION & YEAR ($/tCO2) | Color intensity = price level
A2: Jurisdiction | B2: 2015 | C2: 2016 | D2: 2017 | E2: 2018 | F2: 2019 | G2: 2020 | H2: 2021 | I2: 2022 | J2: 2023
A3: Uruguay | I3: 137.3 | J3: 155.87
A4: Switzerland | B4: 37.17 | C4: 47.705 | D4: 45.435 | E4: 55.1 | F4: 52.245 | G4: 59.645 | H4: 73.785 | I4: 97.725 | J4: 112.31
A5: United Kingdom | B5: 26.71 | C5: 23.72 | D5: 22.41 | E5: 25.46 | F5: 23.59 | G5: 22.28 | H5: 24.8 | I5: 61.32 | J5: 55.205
A6: EU | B6: 7.68 | C6: 4.87 | D6: 5.64 | E6: 16.37 | F6: 24.51 | G6: 18.54 | H6: 49.78 | I6: 86.53 | J6: 96.3
A7: Finland | B7: 47.42 | C7: 64.02 | D7: 64.14 | E7: 78.11 | F7: 73.04 | G7: 71.08 | H7: 76.34 | I7: 71.84 | J7: 70.69
A8: Norway | B8: 63.24 | C8: 62.08 | D8: 63.94 | E8: 74.45 | F8: 67.15 | G8: 58.94 | H8: 60.76 | I8: 54.27 | J8: 50.14
A9: France | B9: 15.59 | C9: 24.56 | D9: 32.61 | E9: 55.3 | F9: 50.11 | G9: 48.77 | H9: 52.39 | I9: 49.29 | J9: 48.5
A10: Ireland | B10: 21.51 | C10: 22.32 | D10: 21.38 | E10: 24.8 | F10: 22.47 | G10: 28.43 | H10: 39.35 | I10: 45.31 | J10: 52.74
A11: New Zealand | B11: 4.93 | C11: 13.03 | D11: 12.51 | E11: 15.22 | F11: 17.53 | G11: 14.3 | H11: 25.76 | I11: 52.62 | J11: 34.2
A12: Alberta | B12: 11.89 | C12: 15.37 | D12: 18.785 | E12: 23.25 | F12: 22.49 | G12: 21.1 | H12: 31.83 | I12: 39.96 | J12: 48.03
A13: British Columbia | B13: 23.78 | C13: 23.06 | D13: 22.54 | E13: 27.13 | F13: 29.99 | G13: 28.14 | H13: 27.855 | I13: 29.97 | J13: 33.25
A14: Canada | F14: 15 | G14: 21.1 | H14: 31.83 | I14: 39.96 | J14: 48.03
A15: New Brunswick | G15: 21.1 | H15: 31.83 | I15: 39.96 | J15: 48.03
A16: Newfoundland and Labrador | F16: 15 | G16: 14.07 | H16: 23.88 | I16: 39.96 | J16: 48.03
A17: Northwest Territories | G17: 14.07 | H17: 23.88 | I17: 31.97 | J17: 48.03
A18: Ontario | D18: 14.06 | E18: 11.7 | I18: 31.97 | J18: 48.03
A19: Saskatchewan | H19: 31.83 | I19: 39.96 | J19: 48.03
A20: Luxembourg | H20: 40.12 | I20: 41.76 | J20: 46.56
A21: Netherlands | H21: 35.24 | I21: 46.14 | J21: 39.33
A22: Tokyo | B22: 37.51 | C22: 14.64 | D22: 13.39 | E22: 5.69 | F22: 5.85 | G22: 5.58 | H22: 4.87 | I22: 4.42 | J22: 41.95
A23: Quebec | B23: 12.49 | C23: 12.8 | D23: 15.08 | E23: 15.1 | F23: 15.77 | G23: 21.75 | H23: 17.94 | I23: 38.58 | J23: 29.84
A24: Saitama | B24: 37.51 | C24: 14.64 | D24: 13.39 | E24: 5.69 | F24: 5.85 | G24: 5.58 | H24: 5.42 | I24: 3.84 | J24: 1.08
A25: Iceland | B25: 16.6 | C25: 19 | D25: 21.64 | E25: 37.48 | F25: 36.24 | G25: 21.15 | H25: 23.7 | I25: 24.23 | J25: 24.15
A26: Portugal | B26: 4.5 | C26: 7.26 | D26: 6.97 | E26: 6.86 | F26: 12.78 | G26: 37.27 | H26: 27.99 | I26: 26.34 | J26: 25.92
A29: LEGEND: □ No data ■ <$10 ■ $10–25 ■ $25–50 ■ $50–75 ■ $75–100 ■ >$100

Sheet Econ_Analysis
B1: ECONOMETRIC ANALYSIS | Carbon Pricing Effectiveness & Policy Evaluation
B3: A. DESCRIPTIVE STATISTICS BY REGION (Carbon Price, $/tCO2)
B4: Region | C4: N (obs) | D4: Mean Price | E4: Median | F4: Std Dev | G4: Min | H4: Max | I4: Avg Emissions (MtCO2)
B5: Europe | C5: =COUNTIF(Analysis!F2:F1000,"Europe") -> 161 | D5: =AVERAGEIFS(Analysis!C2:C1000,Analysis!F2:F1000,"Europe") -> 31.783851 | E5: =MEDIAN(IF(Analysis!F2:F1000="Europe",Analysis!C2:C1000)) -> 0 | F5: 23.72 | G5: 0.01 | H5: 130.81 | I5: =AVERAGEIFS(Analysis!E2:E1000,Analysis!F2:F1000,"Europe") -> 319.66093
B6: North America | C6: =COUNTIF(Analysis!F2:F1000,"North America") -> 42 | D6: =AVERAGEIFS(Analysis!C2:C1000,Analysis!F2:F1000,"North America") -> 26.121429 | E6: =MEDIAN(IF(Analysis!F2:F1000="North America",Analysis!C2:C1000)) -> 14.085 | F6: 22.8 | G6: 11.89 | H6: 48.03 | I6: =AVERAGEIFS(Analysis!E2:E1000,Analysis!F2:F1000,"North America") -> 1970.106
B7: Latin America | C7: =COUNTIF(Analysis!F2:F1000,"Latin America") -> 39 | D7: =AVERAGEIFS(Analysis!C2:C1000,Analysis!F2:F1000,"Latin America") -> 13.472308 | E7: =MEDIAN(IF(Analysis!F2:F1000="Latin America",Analysis!C2:C1000)) -> 0 | F7: 5 | G7: 0 | H7: 155.87 | I7: =AVERAGEIFS(Analysis!E2:E1000,Analysis!F2:F1000,"Latin America") -> 448.29282
B8: Asia-Pacific | C8: =COUNTIF(Analysis!F2:F1000,"Asia-Pacific") -> 100 | D8: =AVERAGEIFS(Analysis!C2:C1000,Analysis!F2:F1000,"Asia-Pacific") -> 5.834 | E8: =MEDIAN(IF(Analysis!F2:F1000="Asia-Pacific",Analysis!C2:C1000)) -> 0 | F8: 4.13 | G8: 0.22 | H8: 52.62 | I8: =AVERAGEIFS(Analysis!E2:E1000,Analysis!F2:F1000,"Asia-Pacific") -> 8753.4303
B9: Africa | C9: =COUNTIF(Analysis!F2:F1000,"Africa") -> 4 | D9: =AVERAGEIFS(Analysis!C2:C1000,Analysis!F2:F1000,"Africa") -> 8.745 | E9: =MEDIAN(IF(Analysis!F2:F1000="Africa",Analysis!C2:C1000)) -> 0 | F9: 9.04 | G9: 7.06 | H9: 9.84 | I9: =AVERAGEIFS(Analysis!E2:E1000,Analysis!F2:F1000,"Africa") -> 439.0525
B10: Other | C10: =COUNTIF(Analysis!F2:F1000,"Other") -> 86 | D10: =AVERAGEIFS(Analysis!C2:C1000,Analysis!F2:F1000,"Other") -> 20.25814 | E10: =MEDIAN(IF(Analysis!F2:F1000="Other",Analysis!C2:C1000)) -> 0 | F10: 15.58 | G10: 0.5 | H10: 48.03 | I10: =AVERAGEIFS(Analysis!E2:E1000,Analysis!F2:F1000,"Other") -> 1587.5899
B11: ALL | C11: =COUNTA(Analysis!A2:A1000) -> 433 | D11: =AVERAGEIF(Analysis!C2:C1000,">0") -> 21.114385 | E11: =MEDIAN(Analysis!C2:C1000) -> 14.085 | F11: 14.08 | G11: 0 | H11: 155.87 | I11: =AVERAGEIF(Analysis!C2:C1000,">0",Analysis!E2:E1000) -> 2703.1106
B13: B. YEAR-ON-YEAR PRICE EVOLUTION (Avg Carbon Price, $/tCO2)
B14: Year | C14: Avg Price ($/tCO2) | D14: Carbon Tax Avg | E14: ETS Avg | F14: YoY Change | G14: CAGR from 2015 | H14: Avg Emissions (MtCO2) | I14: Emissions vs 2015 (Index)
B15: 2015 | C15: =AVERAGEIF(Analysis!B2:B1000,2015,Analysis!C2:C1000) -> 15.653143 | D15: =AVERAGEIFS(Analysis!C2:C1000,Analysis!B2:B1000,2015,Analysis!D2:D1000,"Carbon tax") -> 21.014706 | E15: =AVERAGEIFS(Analysis!C2:C1000,Analysis!B2:B1000,2015,Analysis!D2:D1000,"ETS") -> 10.589444 | F15: - | G15: - | H15: =AVERAGEIF(Analysis!B2:B1000,2015,Analysis!E2:E1000) -> 2886.7229 | I15: 100
B16: 2016 | C16: =AVERAGEIF(Analysis!B2:B1000,2016,Analysis!C2:C1000) -> 16.113636 | D16: =AVERAGEIFS(Analysis!C2:C1000,Analysis!B2:B1000,2016,Analysis!D2:D1000,"Carbon tax") -> 24.511875 | E16: =AVERAGEIFS(Analysis!C2:C1000,Analysis!B2:B1000,2016,Analysis!D2:D1000,"ETS") -> 8.2094118 | F16: =(C16-C15)/C15 -> 0.029418597 | G16: =(C16/C15)^(1/1)-1 -> 0.029418597 | H16: =AVERAGEIF(Analysis!B2:B1000,2016,Analysis!E2:E1000) -> 3047.087 | I16: =IFERROR(H16/H15*100, "-") -> 105.55523
B17: 2017 | C17: =AVERAGEIF(Analysis!B2:B1000,2017,Analysis!C2:C1000) -> 15.09225 | D17: =AVERAGEIFS(Analysis!C2:C1000,Analysis!B2:B1000,2017,Analysis!D2:D1000,"Carbon tax") -> 20.726667 | E17: =AVERAGEIFS(Analysis!C2:C1000,Analysis!B2:B1000,2017,Analysis!D2:D1000,"ETS") -> 8.8647368 | F17: =(C17-C16)/C16 -> -0.06338646 | G17: =(C17/C15)^(1/2)-1 -> -0.01807974 | H17: =AVERAGEIF(Analysis!B2:B1000,2017,Analysis!E2:E1000) -> 2913.6205 | I17: =IFERROR(H17/H15*100, "-") -> 100.93177
B18: 2018 | C18: =AVERAGEIF(Analysis!B2:B1000,2018,Analysis!C2:C1000) -> 18.004048 | D18: =AVERAGEIFS(Analysis!C2:C1000,Analysis!B2:B1000,2018,Analysis!D2:D1000,"Carbon tax") -> 25.154783 | E18: =AVERAGEIFS(Analysis!C2:C1000,Analysis!B2:B1000,2018,Analysis!D2:D1000,"ETS") -> 9.3478947 | F18: =(C18-C17)/C17 -> 0.1929333 | G18: =(C18/C15)^(1/3)-1 -> 0.047746458 | H18: =AVERAGEIF(Analysis!B2:B1000,2018,Analysis!E2:E1000) -> 2890.9714 | I18: =IFERROR(H18/H15*100, "-") -> 100.14718
B19: 2019 | C19: =AVERAGEIF(Analysis!B2:B1000,2019,Analysis!C2:C1000) -> 16.921778 | D19: =AVERAGEIFS(Analysis!C2:C1000,Analysis!B2:B1000,2019,Analysis!D2:D1000,"Carbon tax") -> 21.816296 | E19: =AVERAGEIFS(Analysis!C2:C1000,Analysis!B2:B1000,2019,Analysis!D2:D1000,"ETS") -> 9.58 | F19: =(C19-C18)/C18 -> -0.060112585 | G19: =(C19/C15)^(1/4)-1 -> 0.019673446 | H19: =AVERAGEIF(Analysis!B2:B1000,2019,Analysis!E2:E1000) -> 2771.8549 | I19: =IFERROR(H19/H15*100, "-") -> 96.020818
B20: 2020 | C20: =AVERAGEIF(Analysis!B2:B1000,2020,Analysis!C2:C1000) -> 16.947347 | D20: =AVERAGEIFS(Analysis!C2:C1000,Analysis!B2:B1000,2020,Analysis!D2:D1000,"Carbon tax") -> 21.532069 | E20: =AVERAGEIFS(Analysis!C2:C1000,Analysis!B2:B1000,2020,Analysis!D2:D1000,"ETS") -> 10.2995 | F20: =(C20-C19)/C19 -> 0.001511021 | G20: =(C20/C15)^(1/5)-1 -> 0.0160148 | H20: =AVERAGEIF(Analysis!B2:B1000,2020,Analysis!E2:E1000) -> 2662.8786 | I20: =IFERROR(H20/H15*100, "-") -> 92.24573
B21: 2021 | C21: =AVERAGEIF(Analysis!B2:B1000,2021,Analysis!C2:C1000) -> 20.826379 | D21: =AVERAGEIFS(Analysis!C2:C1000,Analysis!B2:B1000,2021,Analysis!D2:D1000,"Carbon tax") -> 24.653438 | E21: =AVERAGEIFS(Analysis!C2:C1000,Analysis!B2:B1000,2021,Analysis!D2:D1000,"ETS") -> 16.116154 | F21: =(C21-C20)/C20 -> 0.22888729 | G21: =(C21/C15)^(1/6)-1 -> 0.048742104 | H21: =AVERAGEIF(Analysis!B2:B1000,2021,Analysis!E2:E1000) -> 2468.3503 | I21: =IFERROR(H21/H15*100, "-") -> 85.507008
B22: 2022 | C22: =AVERAGEIF(Analysis!B2:B1000,2022,Analysis!C2:C1000) -> 28.461587 | D22: =AVERAGEIFS(Analysis!C2:C1000,Analysis!B2:B1000,2022,Analysis!D2:D1000,"Carbon tax") -> 30.671818 | E22: =AVERAGEIFS(Analysis!C2:C1000,Analysis!B2:B1000,2022,Analysis!D2:D1000,"ETS") -> 26.030333 | F22: =(C22-C21)/C21 -> 0.36661236 | G22: =(C22/C15)^(1/7)-1 -> 0.089165655 | H22: =AVERAGEIF(Analysis!B2:B1000,2022,Analysis!E2:E1000) -> 2508.3332 | I22: =IFERROR(H22/H15*100, "-") -> 86.892068
B23: 2023 | C23: =AVERAGEIF(Analysis!B2:B1000,2023,Analysis!C2:C1000) -> 30.864478 | D23: =AVERAGEIFS(Analysis!C2:C1000,Analysis!B2:B1000,2023,Analysis!D2:D1000,"Carbon tax") -> 32.099143 | E23: =AVERAGEIFS(Analysis!C2:C1000,Analysis!B2:B1000,2023,Analysis!D2:D1000,"ETS") -> 29.514063 | F23: =(C23-C22)/C22 -> 0.084425731 | G23: =(C23/C15)^(1/8)-1 -> 0.088572034 | H23: =AVERAGEIF(Analysis!B2:B1000,2023,Analysis!E2:E1000) -> 2527.8601 | I23: =IFERROR(H23/H15*100, "-") -> 87.568508
B26: C. CARBON TAX vs. ETS COMPARISON (Policy Effectiveness Matrix)
B27: Metric | C27: Carbon Tax | D27: ETS | E27: Difference (ETS−Tax) | F27: Interpretation
B28: Observations (N) | C28: =COUNTIF(Analysis!D2:D1000,"Carbon tax") -> 233 | D28: =COUNTIF(Analysis!D2:D1000,"ETS") -> 199 | E28: =D29-C29 -> -9.2519046 | F28: ETS covers more jurisdictions
B29: Mean Price ($/tCO2) | C29: =AVERAGEIF(Analysis!D2:D1000,"Carbon tax",Analysis!C2:C1000) -> 25.327382 | D29: =AVERAGEIF(Analysis!D2:D1000,"ETS",Analysis!C2:C1000) -> 16.075477 | E29: =D30-C30 -> 23.613986 | F29: + = ETS priced higher on average
B30: Std Dev of Price | C30: =IFERROR(STDEV(IF(Analysis!D2:D1000="Carbon tax",Analysis!C2:C1000)),0) -> 0 | D30: =IFERROR(STDEV(IF(Analysis!D2:D1000="ETS",Analysis!C2:C1000)),0) -> 23.613986 | E30: =D31-C31 -> 5093.8777 | F30: + = ETS more price-volatile
B31: Mean Emissions (MtCO2) | C31: =AVERAGEIF(Analysis!D2:D1000,"Carbon tax",Analysis!E2:E1000) -> 351.02682 | D31: =AVERAGEIF(Analysis!D2:D1000,"ETS",Analysis!E2:E1000) -> 5444.9045 | E31: =D32-C32 -> 10389.744 | F31: + = ETS jurisdictions emit more
B32: Revenue Proxy ($M) | C32: =AVERAGEIF(Analysis!D2:D1000,"Carbon tax",Analysis!G2:G1000) -> 2006.5119 | D32: =AVERAGEIF(Analysis!D2:D1000,"ETS",Analysis!G2:G1000) -> 12396.256 | E32: =D33-C33 -> -0.59727192 | F32: Avg estimated annual revenue
B33: Price per MtCO2 (Intensity) | C33: =AVERAGEIF(Analysis!D2:D1000,"Carbon tax",Analysis!H2:H1000) -> 0.65548313 | D33: =AVERAGEIF(Analysis!D2:D1000,"ETS",Analysis!H2:H1000) -> 0.058211215 | E33: =D34-C34 -> 0 | F33: Price intensity (efficiency proxy)
B36: D. LOG-LINEAR ELASTICITY ESTIMATION SETUP (ln Emissions = α + β·ln Price + ε)
B37: The elasticity of emissions with respect to carbon price measures the % change in emissions for a 1% increase in price. We estimate: ln(Emissions_it) = α + β·ln(Price_it) + γ_i + δ_t + ε_it where γ_i = jurisdiction fixed effects (controls for time-invariant differences), δ_t = year fixed effects (controls for global shocks), β = price elasticity of emissions.
B39: → To run OLS in Excel:
B40: 1. Copy columns Log_Price (I) and Log_Emissions (J) from Analysis sheet
B41: 2. Use Data → Data Analysis → Regression (add-in) with Y=Log_Emissions, X=Log_Price
B42: 3. The coefficient on Log_Price = estimated price elasticity of emissions (expect β < 0)
B43: 4. For panel FE: subtract jurisdiction means from each variable before regressing (within transformation)
B44: 5. Robust SE: use the LINEST() function or copy to Stata/R for clustered standard errors
B45: → Stata code: xtreg log_emissions log_price, fe robust cluster(jurisdiction)
B46: → R code: felm(log_emissions ~ log_price | jurisdiction + year | 0 | jurisdiction, data=df)
B48: E. PRICE ADEQUACY vs. SOCIAL COST OF CARBON ($/tCO2, High-Income Country Estimates)
...

Sheet Chart_Scatter
A1: SCATTER: Carbon Price vs. Emissions | Latest year per jurisdiction
A2: Jurisdiction | B2: Carbon_Price_USD | C2: Emissions_MtCO2 | D2: Policy_Type | E2: Region | F2: Log_Price | G2: Log_Emissions
A3: Alberta | B3: 48.03 | C3: 875.95 | D3: ETS | E3: North America | F3: 3.8718 | G3: 6.7753
A4: Argentina | B4: 4.97 | C4: 435.28 | D4: Carbon tax | E4: Latin America | F4: 1.6034 | G4: 6.076
A5: Austria | B5: 35.34 | C5: 61.93 | D5: ETS | E5: Europe | F5: 3.565 | G5: 4.126
A6: Baja California | B6: 8.32 | C6: 676.79 | D6: Carbon tax | E6: Latin America | F6: 2.1187 | G6: 6.5174
A7: Beijing | B7: 12.96 | C7: 13152.05 | D7: ETS | E7: Asia-Pacific | F7: 2.5619 | G7: 9.4843
A8: British Columbia | B8: 48.03 | C8: 875.95 | D8: Carbon tax | E8: North America | F8: 3.8718 | G8: 6.7753
A9: California | B9: 29.84 | C9: 5434.18 | D9: ETS | E9: North America | F9: 3.3958 | G9: 8.6005
A10: Canada | B10: 48.03 | C10: 875.95 | D10: Carbon tax | E10: North America | F10: 3.8718 | G10: 6.7753
A11: Chile | B11: 5 | C11: 102.71 | D11: Carbon tax | E11: Latin America | F11: 1.6094 | G11: 4.6319
A12: China | B12: 8.15 | C12: 13152.05 | D12: ETS | E12: Asia-Pacific | F12: 2.098 | G12: 9.4843
A13: Chongqing | B13: 4.66 | C13: 13152.05 | D13: ETS | E13: Asia-Pacific | F13: 1.539 | G13: 9.4843
A14: Colombia | B14: 5.06 | C14: 294.08 | D14: Carbon tax | E14: Latin America | F14: 1.6214 | G14: 5.6839
... A64: Zacatecas | B64: 13.86 | C64: 731.02 | D64: Carbon tax | E64: Latin America | F64: 2.629 | G64: 6.5944

Sheet Chart_PriceTrends
A1: CARBON PRICE TRENDS | Average Price by Policy Type (2015–2023, $/tCO2)
A2: Year | B2: Overall Avg | C2: Carbon Tax Avg | D2: ETS Avg | E2: Europe Avg | F2: N.America Avg | G2: Asia-Pacific Avg | H2: Latin America Avg
A3: 2015 | B3: 15.65 | C3: 21.01 | D3: 10.59 | E3: 20.7 | F3: 16.05 | G3: 4.52
A4: 2016 | B4: 16.11 | C4: 24.51 | D4: 8.21 | E4: 25.22 | F4: 17.08 | G4: 4.18 | H4: 2.16
A5: 2017 | B5: 15.09 | C5: 20.73 | D5: 8.86 | E5: 23.93 | F5: 18.8 | G5: 4.27 | H5: 6.22
A6: 2018 | B6: 18 | C6: 25.15 | D6: 9.35 | E6: 30.33 | F6: 22.18 | G6: 5.33 | H6: 7.09
A7: 2019 | B7: 16.92 | C7: 21.82 | D7: 9.58 | E7: 28.7 | F7: 21.15 | G7: 4.73 | H7: 5.98
A8: 2020 | B8: 16.95 | C8: 21.53 | D8: 10.3 | E8: 29.55 | F8: 21.41 | G8: 4.86 | H8: 5.53
A9: 2021 | B9: 20.83 | C9: 24.65 | D9: 16.12 | E9: 34.67 | F9: 28.19 | G9: 5.33 | H9: 5.68
A10: 2022 | B10: 28.46 | C10: 30.67 | D10: 26.03 | E10: 42.01 | F10: 35.11 | G10: 9 | H10: 28
A11: 2023 | B11: 30.86 | C11: 32.1 | D11: 29.51 | E11: 43.93 | F11: 37.52 | G11: 8.7 | H11: 29.03

Sheet Data_Pricing
A1: Jurisdiction | B1: Year | C1: Carbon_Price_USD | D1: Policy_Type | E1: Region | F1: Price_Real_2023USD | G1: Source_Note
A2: Albania | B2: 2024 | C2: 13.11 | D2: Carbon tax | E2: Europe | F2: 12.73 | G2: World Bank State and Trends of Carbon Pricing 2024
A3: Alberta | B3: 2015 | C3: 11.89 | D3: ETS | E3: North America | F3: 14.15 | G3: World Bank State and Trends of Carbon Pricing 2024
A4: Alberta | B4: 2016 | C4: 15.37 | D4: ETS | E4: North America | F4: 18.08 | G4: World Bank State and Trends of Carbon Pricing 2024
A5: Alberta | B5: 2017 | C5: 15.03 | D5: Carbon tax | E5: North America | F5: 17.28 | G5: World Bank State and Trends of Carbon Pricing 2024
A6: Alberta | B6: 2017 | C6: 22.54 | D6: ETS | E6: North America | F6: 25.91 | G6: World Bank State and Trends of Carbon Pricing 2024
A7: Alberta | B7: 2018 | C7: 23.25 | D7: Carbon tax | E7: North America | F7: 26.12 | G7: World Bank State and Trends of Carbon Pricing 2024
A8: Alberta | B8: 2018 | C8: 23.25 | D8: ETS | E8: North America | F8: 26.12 | G8: World Bank State and Trends of Carbon Pricing 2024
A9: Alberta | B9: 2019 | C9: 22.49 | D9: Carbon tax | E9: North America | F9: 24.71 | G9: World Bank State and Trends of Carbon Pricing 2024
A10: Alberta | B10: 2019 | C10: 22.49 | D10: ETS | E10: North America | F10: 24.71 | G10: World Bank State and Trends of Carbon Pricing 2024
A11: Alberta | B11: 2020 | C11: 21.1 | D11: ETS | E11: North America | F11: 23.19 | G11: World Bank State and Trends of Carbon Pricing 2024
A12: Alberta | B12: 2021 | C12: 31.83 | D12: ETS | E12: North America | F12: 33.51 | G12: World Bank State and Trends of Carbon Pricing 2024
A13: Alberta | B13: 2022 | C13: 39.96 | D13: ETS | E13: North America | F13: 38.8 | G13: World Bank State and Trends of Carbon Pricing 2024
... A513: Zacatecas | B513: 2024 | C513: 15.09 | D513: Carbon tax | E513: Latin America | F513: 14.65 | G513: World Bank State and Trends of Carbon Pricing 2024

Sheet Data_Emissions
A1: Jurisdiction | B1: Year | C1: Emissions_MtCO2 | D1: Region | E1: Emissions_Index_2015 | F1: YoY_Change_Pct
A2: Albania | B2: 2015 | C2: 12.27 | D2: Europe | E2: 100
A3: Albania | B3: 2016 | C3: 9.03 | D3: Europe | E3: 73.6 | F3: -26.41
A4: Albania | B4: 2017 | C4: 9.83 | D4: Europe | E4: 80.1 | F4: 8.86
A5: Albania | B5: 2018 | C5: 9.65 | D5: Europe | E5: 78.6 | F5: -1.83
A6: Albania | B6: 2019 | C6: 9.23 | D6: Europe | E6: 75.2 | F6: -4.35
A7: Albania | B7: 2020 | C7: 8.69 | D7: Europe | E7: 70.8 | F7: -5.85
A8: Albania | B8: 2021 | C8: 9.82 | D8: Europe | E8: 80 | F8: 13
A9: Albania | B9: 2022 | C9: 8.96 | D9: Europe | E9: 73 | F9: -8.76
A10: Albania | B10: 2023 | C10: 8.56 | D10: Europe | E10: 69.8 | F10: -4.46
A11: Alberta | B11: 2015 | C11: 789.07 | D11: North America | E11: 100
A12: Alberta | B12: 2016 | C12: 886.24 | D12: North America | E12: 112.3 | F12: 12.31
A13: Alberta | B13: 2017 | C13: 905.03 | D13: North America | E13: 114.7 | F13: 2.12
A14: Alberta | B14: 2018 | C14: 923.96 | D14: North America | E14: 117.1 | F14: 2.09
A15: Alberta | B15: 2019 | C15: 915.12 | D15: North America | E15: 116 | F15: -0.96
A16: Alberta | B16: 2020 | C16: 853.61 | D16: North America | E16: 108.2 | F16: -6.72
A17: Alberta | B17: 2021 | C17: 844.41 | D17: North America | E17: 107 | F17: -1.08
A18: Alberta | B18: 2022 | C18: 857.27 | D18: North America | E18: 108.6 | F18: 1.52
A19: Alberta | B19: 2023 | C19: 875.95 | D19: North America | E19: 111 | F19: 2.18
A20: Argentina | B20: 2015 | C20: 456.99 | D20: Latin America | E20: 100
A21: Argentina | B21: 2016 | C21: 440.31 | D21: Latin America | E21: 96.4 | F21: -3.65
A22: Argentina | B22: 2017 | C22: 444.53 | D22: Latin America | E22: 97.3 | F22: 0.96
A23: Argentina | B23: 2018 | C23: 442.66 | D23: Latin America | E23: 96.9 | F23: -0.42
A24: Argentina | B24: 2019 | C24: 439.79 | D24: Latin America | E24: 96.2 | F24: -0.65
A25: Argentina | B25: 2020 | C25: 425.46 | D25: Latin America | E25: 93.1 | F25: -3.26
A26: Argentina | B26: 2021 | C26: 430.48 | D26: Latin America | E26: 94.2 | F26: 1.18
A27: Argentina | B27: 2022 | C27: 450.36 | D27: Latin America | E27: 98.5 | F27: 4.62
A28: Argentina | B28: 2023 | C28: 435.28 | D28: Latin America | E28: 95.2 | F28: -3.35
A29: Australia | B29: 2015 | C29: 616.51 | D29: Asia-Pacific | E29: 100
A30: Australia | B30: 2016 | C30: 595.68 | D30: Asia-Pacific | E30: 96.6 | F30: -3.38
A31: Australia | B31: 2017 | C31: 638.33 | D31: Asia-Pacific | E31: 103.5 | F31: 7.16
A32: Australia | B32: 2018 | C32: 634.06 | D32: Asia-Pacific | E32: 102.8 | F32: -0.67
A33: Australia | B33: 2019 | C33: 618.18 | D33: Asia-Pacific | E33: 100.3 | F33: -2.5
A34: Australia | B34: 2020 | C34: 568.79 | D34: Asia-Pacific | E34: 92.3 | F34: -7.99
A35: Australia | B35: 2021 | C35: 569.42 | D35: Asia-Pacific | E35: 92.4 | F35: 0.11
A36: Australia | B36: 2022 | C36: 565.82 | D36: Asia-Pacific | E36: 91.8 | F36: -0.63
A37: Australia | B37: 2023 | C37: 651.66 | D37: Asia-Pacific | E37: 105.7 | F37: 15.17
A38: Austria | B38: 2015 | C38: 72.02 | D38: Europe | E38: 100
A39: Austria | B39: 2016 | C39: 72.33 | D39: Europe | E39: 100.4 | F39: 0.43
A40: Austria | B40: 2017 | C40: 74.39 | D40: Europe | E40: 103.3 | F40: 2.85
...

Sheet Methodology
B1: DATA SOURCES
B3: DATA SOURCES
B4: • World Bank — State and Trends of Carbon Pricing (2024) | C4: Primary source for carbon price levels, policy types, jurisdictions. Annual publication. URL: openknowledge.worldbank.org
B5: • EDGAR / IEA / Our World in Data | C5: Emissions data (MtCO2e). Cross-validated against UNFCCC national inventories for country-level jurisdictions.
B6: • IMF Fiscal Monitor (Oct 2023) | C6: Social Cost of Carbon benchmarks, IMF indicative price corridors. USD deflator/CPI inflation adjustment.
B7: • World Bank CPI Data | C7: Used to deflate nominal prices to 2023 USD (column: Price_Real_2023USD in Data_Pricing sheet).
B8: • EU ETS Historical Prices | C8: EUAs (European Union Allowances) spot prices from ICE/Refinitiv via public records.
B11: ACADEMIC REFERENCES
B12: • Goulder & Schein (2013) | C12: Carbon taxes versus cap-and-trade: a critical review. Climate Change Economics.
B13: • Metcalf (2019) | C13: On the economics of a carbon tax for the United States. Brookings Papers on Economic Activity.
B14: • World Bank (2024) | C14: State and Trends of Carbon Pricing. Washington, DC: World Bank Group.
B15: • Stiglitz & Stern (2017) | C15: Report of the High-Level Commission on Carbon Prices. Carbon Pricing Leadership Coalition.
B16: • Nordhaus (2017) | C16: Revisiting the social cost of carbon. PNAS 114(7): 1518–1523.
B17: • EU ETS Innovation Fund | C17: https://climate.ec.europa.eu/eu-action/funding-climate-action/innovation-fund_en

Sheet DB_Helper
A2: All | B2: All | C2: 2015 | D2: 2015
A3: Africa | B3: Carbon tax | C3: 2016 | D3: 2016
A4: Asia-Pacific | B4: ETS | C4: 2017 | D4: 2017
A5: Europe | C5: 2018 | D5: 2018
A6: Latin America | C6: 2019 | D6: 2019
A7: North America | C7: 2020 | D7: 2020
A8: Other | C8: 2021 | D8: 2021
C9: 2022 | D9: 2022
C10: 2023 | D10: 2023
